Workbook

Sheet Summary
C2: Students to fill in the red cells below:
B3: Course Code: | C3: TPJ655 - Section X
B4: Course Instructor: | C4: David Jong
B5: Instructor email: | C5: david.jong@senecapolytechnic.ca
B8: Group Number: | C8: B01
B9: Lecture Room Number:
B10: Lab Room Number:
B13: Proposed Project Name:
B14: Project Manager 1: | D14: PM1
B15: PM1 school email: | D15: PM1
B16: Project Manager 2: | D16: PM2
B17: PM2 school email: | D17: PM2
B21: Week 1 Course Start Date: | C21: Monday | D21: 46146
B22: Week 1 Lecture Date: | C22: Tuesday | D22: =Summary!$D$21+1 -> 46147
B23: Week 1 Lab Date: | C23: Wednesday | D23: =Summary!$D$21+3 -> 46149
B24: Due Dates for Dropboxes: | C24: Saturdays by 11:45AM (morning) | D24: =Summary!$D$21+6+7 -> 46159

Sheet Budget
C2: What value in CAD is your team expecting to spend on your project, in total? Include what you actually spend to see how your estimations track.
B4: Index | C4: Item Name | D4: Description | E4: Part Number (P/N) | F4: Qty | G4: $ / item | H4: $ total | I4: $ spent | J4: Index | K4: Link to Item Bought | L4: Link to Datasheet
B5: 1 | F5: 2 | G5: 3.5 | H5: =F5*G5 -> 7 | J5: =B5 -> 1
B6: 2 | F6: 3 | G6: 3 | H6: =F6*G6 -> 9 | J6: =B6 -> 2
B7: 3 | H7: =F7*G7 -> 0 | J7: =B7 -> 3
B8: 4 | H8: =F8*G8 -> 0 | J8: =B8 -> 4
B9: 5 | H9: =F9*G9 -> 0 | J9: =B9 -> 5
H10: =F10*G10 -> 0 | J10: =B10 -> 0
H11: =F11*G11 -> 0 | J11: =B11 -> 0
H12: =F12*G12 -> 0 | J12: =B12 -> 0
J13: =B13 -> 0
H14: =F14*G14 -> 0 | J14: =B14 -> 0
H15: =F15*G15 -> 0 | J15: =B15 -> 0
H16: =F16*G16 -> 0 | J16: =B16 -> 0
H17: =F17*G17 -> 0 | J17: =B17 -> 0
G18: Total: | H18: =SUM(H5:H17) -> 16

Sheet Bill of Materials
C2: What would someone spend in CAD on this project if they were to recreate it themselves? Include all the materials and components they would need.
B4: Index | C4: Item Name | D4: Description | E4: Manufacturer | F4: Mfr P/N | G4: Qty | H4: $ / item | I4: $ total | J4: $ spent | K4: Index | L4: Supplier | M4: Sup P/N | N4: Link to Item Bought | O4: Link to Datasheet
B5: 1 | G5: 2 | H5: 3.5 | I5: =G5*H5 -> 7 | K5: =B5 -> 1
B6: 2 | G6: 3 | H6: 3 | I6: =G6*H6 -> 9 | K6: =B6 -> 2
B7: 3 | I7: =G7*H7 -> 0 | K7: =B7 -> 3
B8: 4 | I8: =G8*H8 -> 0 | K8: =B8 -> 4
B9: 5 | I9: =G9*H9 -> 0 | K9: =B9 -> 5
I10: =G10*H10 -> 0 | K10: =B10 -> 0
I11: =G11*H11 -> 0 | K11: =B11 -> 0
I12: =G12*H12 -> 0 | K12: =B12 -> 0
I13: =G13*H13 -> 0 | K13: =B13 -> 0
I14: =G14*H14 -> 0 | K14: =B14 -> 0
I15: =G15*H15 -> 0 | K15: =B15 -> 0
I16: =G16*H16 -> 0 | K16: =B16 -> 0
I17: =G17*H17 -> 0 | K17: =B17 -> 0
H18: Total: | I18: =SUM(I5:I17) -> 16

Sheet Contract Rev.1
B2: =Summary!C8 -> B01 | C2: TEAM MANAGERS . | D2: Student Name | E2: Student ID# | F2: CURRENT STATUS: | H2: Notes:
C3: Project Manager 1: | D3: Jane Doe | E3: 000 000 000 | F3: REV.1 - Pending
C4: Project Manager 2: | D4: John Smith | E4: 000 000 000
C7: Item | D7: Student Teams will fill out this column: | I7: Instructor’s Comments:
I8: (Do not modify this column)
B9: 0 | C9: Contract Date | D9: Rev.1 | E9: 46046 | F9: Pending Review | I9: TPJ655
D10: Rev.2 | E10: 46046 | F10: (Not ready)
D11: Rev.3 | E11: 46046 | F11: (Not ready)
D12: Rev.4 | E12: 46046 | F12: (Not ready)
B14: 1 | C14: Project Name | I14: Creative. Unique. Descriptive. <10 words.
B16: 2 | C16: Purpose | D16: Description of Project (100-200 words max.):
I17: Be as descriptive and clear as possible in writing a concise overall purpose of your project.
D19: Description of Input & Output Hardware Types: (don't make a list)
I20: Then, state how all IOs (4+ inputs, 4+ outputs) will be used and interact together as a system. Bold each IO type when you first introduce it.
D22: Description of IoT Dashboard Interactivity:
I23: Finally, include a blurb about your IoT dashboard and what items specifically it will monitor (2+ inputs) and control (2+ outputs).
B25: 3 | C25: Hardware Inputs
D26: Electronics Input Hardware Type: | E26: Part Model # | F26: No. of GPIOs | G26: Type # | H26: Qty: | I26: eg.
G27: 1 | H27: 1 | I27: 1) Ultrasonic sensor, model=HC-SR04, GPIO=2 pins (1 AI, 1 DO), qty=1.
G28: 2 | H28: 1
G29: 3 | H29: 1 | I29: 2) Accelerometer, 6-axis I2C, model=GY-521, GPIO=3 pins (2 DO, 1 AI), qty=2.
G30: 4 | H30: 1
I31: etc.
I33: Expected: 3-5 input types in addition to any pushbuttons or other simple digital inputs.
B38: 4 | C38: Hardware Outputs
D39: Electronics Output Hardware Type: | E39: Part Model # | F39: No. of GPIOs | G39: Type # | H39: Qty: | I39: eg.
G40: 1 | H40: 1 | I40: 1) Servo motor, positional 20kg 5V PWM signal, model=MG995, GPIO=1 pin (1 DO), qty=2.
G41: 2 | H41: 1
G42: 3 | H42: 1 | I42: 2) Linear actuator, 12V 30mm stroke 100:1, model=HLS12, GPIO=1 (1 AO), qty=1.
G43: 4 | H43: 1
I46: Expected: 3-5 output types in addition to any LEDs or other simple digital outputs.
B51: 5 | C51: MCU(s) | D51: 1 – ESP32-XXXX | I51: Primary model name? No Arduino or RPi3/4.
I52: Secondary is optional. Must be justified.
B54: 6 | C54: Other Connectivity | D54: 1 – N/A | I54: Expected other boards? eg. Boost converter, ADC or I2C breakout, Power Reg PCB, Separate WIFI connector, Servo motor expansion.
B57: 7 | C57: Software Application(s)
E58: Team is using this Software (modify/update if needed):
D59: General: | E59: MS Office (Word, PowerPoint, Excel) | I59: Do not use Arduino IDE.
D60: Coding IDE: | I60: Coding: VS Code with PlatformIO extension?
D61: PCB design: | E61: AutoDesk Fusion | I61: PCB Design: AutoDesk Fusion.
D62: Schematic: | E62: AutoDesk Fusion
...

Sheet AI Profiles
B2: Policy on AI use in TPJ655: | C2: Generative AI tools can be a useful resource, but they can also create complications if used improperly. In this course, you may use AI-generated code for your assignments, but your grade will reflect the quality of your final submission. If you rely solely on AI-generated content without understanding the underlying concepts, you will miss out on developing the critical thinking skills this course aims to teach. Using generative AI in "auto-pilot" mode (i.e. Copy & Paste) can result in content that lacks creativity, code will likely contain errors to the point of causing harm to your hardware, and may negatively impact your grade. It is recommended that you focus on building a strong foundation in programming and data transformation. If you choose to use AI-generated code, you must indicate this in your assignment by adding clear comments explaining how and why you used it. This ensures transparency and shows that you understand the work submitted and your role in the project.
B4: Instructions this Semester: | C4: For each section of your Technical Report or Presentation that you write this semester, you are encouraged to critique your writing at least twice. Tell your gen AI tool what kind of 'person' it is going to be by giving it a personality description. After it has introduced itself, ask it to critique your writing sample. Use the specific feedback it provides to make changes to your section -- or not! Sometimes the advice is bad. Repeat the process, using a different profiles. Three suggested AI profiles that you can use this semester are listed below. Add your own for bonus marks. When you submit your work for the Weekly Deliverables on that section, provide the history of your communication with all AI profiles used. Explain why you used the parts that you ended up using.
B8: AI Personality 1: | C8: "Percival", the self-important academic.
B9: Personality Description: | C9: Your name is Percival. You have earned a long list of academic degrees in engineering, statistics, English, philosophy, and business. As a result, you know a lot about a lot of topics. However, you are also a bit of a jerk and other people view you as self-important because you are constantly correcting them, even when they don't ask specific questions. You are still working on your communication skills to your colleagues at a polytechnic institution but it's tough to talk to other people who don't always know what they're talking about. Introduce yourself.
B11: AI Personality 2: | C11: "Sam", the average computer user.
B12: Personality Description: | C12: Your name is Sam. You are a genuinely nice person and enjoy helping others solve problems with troubleshooting and asking questions they may not have thought about. You don't have a lot of formal training with electronics and computers, but you have picked up some expertise over the last decade simply with tinkering with projects, opening up gadgets and fixing them, and also designing and coding simple soldered projects that you found on do-it-yourself websites like Instructables.com. You find it easy to talk to other people and find it interesting when people share their ideas with you. Introduce yourself.
B14: AI Personality 3: | C14: Fill this in!
B15: Keyword Traits:
B16: Personality Description:
B18: Credit: | C18: With thanks to Ethan Mollick and Sidney Shapiro for the AI personality ideas and policy wording above, respectively.

Sheet Schedule and Progress
B2: WBS | C2: Description of Tasks - TPJ655 | G2: Format | H2: Sort | I2: Phase | J2: Week Due | K2: Estimated Date | L2: Progress | M2: Grade % | N2: Marks | Q2: 1 | R2: 2 | S2: 3 | T2: 4 | U2: 5 | V2: 6 | W2: 7 | X2: 8 | Y2: 9 | Z2: 10 | AA2: 11 | AB2: 12 | AC2: 13 | AD2: 14 | AE2: 15
B3: A00 | C3: Week 02 | J3: 2 | Q3: =IF($J3=Q$2,"x","") | R3: x | X3: =IF($J3=X$2,"x","")
B4: A01 | C4: Team Status | D4: Marking Scheme | E4: Briefing | G4: Partners present in Lab | H4: Demo | I4: PH1 | J4: 2 | Q4: =IF($J4=Q$2,"x","") | R4: x | X4: =IF($J4=X$2,"x","")
B5: A01-a | C5: Group Formation of PM1 and PM2 | D5: Project Design & Parameters | G5: Conversation in Lab/Lecture | H5: Demo | I5: PH1 | J5: 2 | K5: 46031 | Q5: =IF($J5=Q$2,"x","") | R5: =IF($J5=R$2,"x","") -> x | S5: =IF($J5=S$2,"x","") | T5: =IF($J5=T$2,"x","") | U5: =IF($J5=U$2,"x","") | V5: =IF($J5=V$2,"x","") | W5: =IF($J5=W$2,"x","") | X5: =IF($J5=X$2,"x","") | ... AE5: =IF($J5=AE$2,"x","")
B6: A01-b | C6: Confirm: Team #, ID, Student Names (ideally during Week 1-2 Lab) | D6: Project Design & Parameters | G6: Conversation in Lab/Lecture | H6: Demo | I6: PH1 | J6: 2 | K6: 46038 | Q6: =IF($J6=Q$2,"x","") | R6: =IF($J6=R$2,"x","") -> x | S6: =IF($J6=S$2,"x","") | T6: =IF($J6=T$2,"x","") | U6: =IF($J6=U$2,"x","") | V6: =IF($J6=V$2,"x","") | W6: =IF($J6=W$2,"x","") | X6: =IF($J6=X$2,"x","") | ... AE6: =IF($J6=AE$2,"x","")
B7: A01-c | C7: Confirm: Each member creates a GitHub account | D7: Project Design & Parameters | G7: Conversation in Lab/Lecture | H7: Demo | I7: PH1 | J7: 2 | Q7: =IF($J7=Q$2,"x","") | R7: =IF($J7=R$2,"x","") -> x | S7: =IF($J7=S$2,"x","") | T7: =IF($J7=T$2,"x","") | U7: =IF($J7=U$2,"x","") | V7: =IF($J7=V$2,"x","") | W7: =IF($J7=W$2,"x","") | X7: =IF($J7=X$2,"x","") | ... AE7: =IF($J7=AE$2,"x","")
B8: A01-d | C8: Basic: System Block Diagram (sketch) | D8: Documentation | G8: Demonstration in Lab | H8: Demo | I8: PH1 | J8: 2 | K8: 46038 | Q8: =IF($J8=Q$2,"x","") | R8: =IF($J8=R$2,"x","") -> x | S8: =IF($J8=S$2,"x","") | T8: =IF($J8=T$2,"x","") | U8: =IF($J8=U$2,"x","") | V8: =IF($J8=V$2,"x","") | W8: =IF($J8=W$2,"x","") | X8: =IF($J8=X$2,"x","") | ... AE8: =IF($J8=AE$2,"x","")
B9: A01-d | C9: Basic: Mechanical Drawing of entire project (sketch) | D9: Documentation | G9: Demonstration in Lab | H9: Demo | I9: PH1 | J9: 2 | K9: 46038 | Q9: =IF($J9=Q$2,"x","") | R9: =IF($J9=R$2,"x","") -> x | S9: =IF($J9=S$2,"x","") | T9: =IF($J9=T$2,"x","") | U9: =IF($J9=U$2,"x","") | V9: =IF($J9=V$2,"x","") | W9: =IF($J9=W$2,"x","") | X9: =IF($J9=X$2,"x","") | ... AE9: =IF($J9=AE$2,"x","")
B10: A01-e | C10: Reminder: Start working on Proposal | D10: Project Design & Parameters | G10: Conversation in Lab/Lecture | I10: PH1 | J10: 2 | Q10: =IF($J10=Q$2,"x","") | R10: =IF($J10=R$2,"x","") -> x | S10: =IF($J10=S$2,"x","") | T10: =IF($J10=T$2,"x","") | U10: =IF($J10=U$2,"x","") | V10: =IF($J10=V$2,"x","") | W10: =IF($J10=W$2,"x","") | X10: =IF($J10=X$2,"x","") | ... AE10: =IF($J10=AE$2,"x","")
B11: A00 | C11: Week 03 | J11: 3 | Q11: =IF($J11=Q$2,"x","") | S11: x | X11: =IF($J11=X$2,"x","")
B12: A02 | C12: Team Status | D12: Marking Scheme | E12: Briefing | G12: Partners present in Lab | H12: Demo | I12: PH1 | J12: 3 | Q12: =IF($J12=Q$2,"x","") | S12: x | X12: =IF($J12=X$2,"x","")
B13: A02-b | C13: Confirm: Each member can access Project Charter via OneDrive | D13: Project Design & Parameters | G13: Demonstration in Lab | H13: Demo | I13: PH1 | J13: 3 | K13: 46038 | Q13: =IF($J13=Q$2,"x","") | R13: =IF($J13=R$2,"x","") | S13: =IF($J13=S$2,"x","") -> x | T13: =IF($J13=T$2,"x","") | U13: =IF($J13=U$2,"x","") | V13: =IF($J13=V$2,"x","") | W13: =IF($J13=W$2,"x","") | X13: =IF($J13=X$2,"x","") | ... AE13: =IF($J13=AE$2,"x","")
B14: A02-c | C14: Confirm: Show GitHub setup for each member's account | D14: Project Design & Parameters | G14: Demonstration in Lab | H14: Demo | I14: PH1 | J14: 3 | K14: 46038 | Q14: =IF($J14=Q$2,"x","") | R14: =IF($J14=R$2,"x","") | S14: =IF($J14=S$2,"x","") -> x | T14: =IF($J14=T$2,"x","") | U14: =IF($J14=U$2,"x","") | V14: =IF($J14=V$2,"x","") | W14: =IF($J14=W$2,"x","") | X14: =IF($J14=X$2,"x","") | ... AE14: =IF($J14=AE$2,"x","")
B15: B01 | C15: Project Charter - include updates to all tabs (esp. Contract, Budget, BOM) | D15: Marking Scheme | E15: Charter | F15: Dropbox1 | G15: Save linked .xlsx, Upload to Blackboard | H15: File | I15: PH1 | J15: 3 | M15: =N15/6 -> 1 | N15: 6 | Q15: =IF($J15=Q$2,"x","") | S15: x | X15: =IF($J15=X$2,"x","")
B16: B01-a | C16: Fill out tabs: Summary, Budget, BOM (start), and CONTRACT | D16: Documentation | H16: File | I16: PH1 | J16: 3 | K16: 46045 | Q16: =IF($J16=Q$2,"x","") | R16: =IF($J16=R$2,"x","") | S16: =IF($J16=S$2,"x","") -> x | T16: =IF($J16=T$2,"x","") | U16: =IF($J16=U$2,"x","") | V16: =IF($J16=V$2,"x","") | W16: =IF($J16=W$2,"x","") | X16: =IF($J16=X$2,"x","") | ... AE16: =IF($J16=AE$2,"x","")
B17: B01-b | C17: Confirm: MCU, identify number of GPIO pins available | D17: Project Design & Parameters | H17: File | I17: PH1 | J17: 3 | K17: 46045 | Q17: =IF($J17=Q$2,"x","") | R17: =IF($J17=R$2,"x","") | S17: =IF($J17=S$2,"x","") -> x | T17: =IF($J17=T$2,"x","") | U17: =IF($J17=U$2,"x","") | V17: =IF($J17=V$2,"x","") | W17: =IF($J17=W$2,"x","") | X17: =IF($J17=X$2,"x","") | ... AE17: =IF($J17=AE$2,"x","")
B18: B01-c | C18: Include all software protocols needed by devices (SPI, I2C, etc.) | D18: Documentation | H18: File | I18: PH1 | J18: 3 | K18: 46045 | Q18: =IF($J18=Q$2,"x","") | R18: =IF($J18=R$2,"x","") | S18: =IF($J18=S$2,"x","") -> x | T18: =IF($J18=T$2,"x","") | U18: =IF($J18=U$2,"x","") | V18: =IF($J18=V$2,"x","") | W18: =IF($J18=W$2,"x","") | X18: =IF($J18=X$2,"x","") | ... AE18: =IF($J18=AE$2,"x","")
B19: B01-d | C19: Include clear purpose of IoT dashboard integration | D19: Project Design & Parameters | H19: File | I19: PH1 | J19: 3 | K19: 46045 | S19: x
B20: B01-e | C20: Include purpose and number of PCBs | D20: Project Design & Parameters | H20: File | I20: PH1 | J20: 3 | K20: 46045 | Q20: =IF($J20=Q$2,"x","") | R20: =IF($J20=R$2,"x","") | S20: =IF($J20=S$2,"x","") -> x | T20: =IF($J20=T$2,"x","") | U20: =IF($J20=U$2,"x","") | V20: =IF($J20=V$2,"x","") | W20: =IF($J20=W$2,"x","") | X20: =IF($J20=X$2,"x","") | ... AE20: =IF($J20=AE$2,"x","")
B21: C01 | C21: Presentation: full project overview - include audio in .pptx | D21: Marking Scheme | E21: Proposal | F21: Dropbox1 | G21: TPJ655_A00_Proposal.pptx | H21: File | I21: PH1 | J21: 3 | M21: =N21/6 -> 5 | N21: 30 | Q21: =IF($J21=Q$2,"x","") | S21: x | X21: =IF($J21=X$2,"x","")
B22: C01-a | C22: Confirm: Category & Purpose, Targeted Industry | D22: Project Design & Parameters | H22: File | I22: PH1 | J22: 3 | K22: 46045 | Q22: =IF($J22=Q$2,"x","") | R22: =IF($J22=R$2,"x","") | S22: =IF($J22=S$2,"x","") -> x | T22: =IF($J22=T$2,"x","") | U22: =IF($J22=U$2,"x","") | V22: =IF($J22=V$2,"x","") | W22: =IF($J22=W$2,"x","") | X22: =IF($J22=X$2,"x","") | ... AE22: =IF($J22=AE$2,"x","")
B23: C01-b | C23: Confirm: Power Requirements: All voltages, input jack / AA batteries | D23: Project Design & Parameters | H23: File | I23: PH1 | J23: 3 | K23: 46045 | Q23: =IF($J23=Q$2,"x","") | R23: =IF($J23=R$2,"x","") | S23: =IF($J23=S$2,"x","") -> x | T23: =IF($J23=T$2,"x","") | U23: =IF($J23=U$2,"x","") | V23: =IF($J23=V$2,"x","") | W23: =IF($J23=W$2,"x","") | X23: =IF($J23=X$2,"x","") | ... AE23: =IF($J23=AE$2,"x","")
B24: C01-c | C24: List: Purpose of each input, each output | D24: Project Design & Parameters | H24: File | I24: PH1 | J24: 3 | K24: 46045 | Q24: =IF($J24=Q$2,"x","") | R24: =IF($J24=R$2,"x","") | S24: =IF($J24=S$2,"x","") -> x | T24: =IF($J24=T$2,"x","") | U24: =IF($J24=U$2,"x","") | V24: =IF($J24=V$2,"x","") | W24: =IF($J24=W$2,"x","") | X24: =IF($J24=X$2,"x","") | ... AE24: =IF($J24=AE$2,"x","")
B25: C01-e | C25: System Block Diagram (SBD) - use Visio or yEd to export .jpg | D25: Technical Report | G25: Intended: Technical Report, section §15A | H25: File | I25: PH1 | J25: 3 | K25: 46045 | Q25: =IF($J25=Q$2,"x","") | R25: =IF($J25=R$2,"x","") | S25: =IF($J25=S$2,"x","") -> x | T25: =IF($J25=T$2,"x","") | U25: =IF($J25=U$2,"x","") | V25: =IF($J25=V$2,"x","") | W25: =IF($J25=W$2,"x","") | X25: =IF($J25=X$2,"x","") | ... AE25: =IF($J25=AE$2,"x","")
B26: C01-f | C26: Mechanical Drawing of entire project | D26: Technical Report | G26: Intended: Technical Report, section §15D | H26: File | I26: PH1 | J26: 3 | K26: 46045 | S26: x
B27: C01-g | C27: Introduction - introduce project, why this idea, hook | D27: Technical Report | G27: Intended: Technical Report, section §04 | H27: File | I27: PH1 | J27: 3 | K27: 46045 | O27: 0 | Q27: =IF($J27=Q$2,"x","") | R27: =IF($J27=R$2,"x","") | S27: =IF($J27=S$2,"x","") -> x | T27: =IF($J27=T$2,"x","") | U27: =IF($J27=U$2,"x","") | V27: =IF($J27=V$2,"x","") | W27: =IF($J27=W$2,"x","") | X27: =IF($J27=X$2,"x","") | ... AE27: =IF($J27=AE$2,"x","")
B28: C01-h | C28: Start Background Research - find 3 similar projects, discuss | D28: Technical Report | G28: Intended: Technical Report, section §05 | H28: File | I28: PH1 | J28: 3 | K28: 46045 | O28: 0 | Q28: =IF($J28=Q$2,"x","") | R28: =IF($J28=R$2,"x","") | S28: =IF($J28=S$2,"x","") -> x | T28: =IF($J28=T$2,"x","") | U28: =IF($J28=U$2,"x","") | V28: =IF($J28=V$2,"x","") | W28: =IF($J28=W$2,"x","") | X28: =IF($J28=X$2,"x","") | ... AE28: =IF($J28=AE$2,"x","")
B29: C01-i | C29: Discuss anticipated challenges in each phase, and their plan | D29: Project Design & Parameters | H29: File | I29: PH1 | J29: 3 | K29: 46045 | Q29: =IF($J29=Q$2,"x","") | R29: =IF($J29=R$2,"x","") | S29: =IF($J29=S$2,"x","") -> x | T29: =IF($J29=T$2,"x","") | U29: =IF($J29=U$2,"x","") | V29: =IF($J29=V$2,"x","") | W29: =IF($J29=W$2,"x","") | X29: =IF($J29=X$2,"x","") | ... AE29: =IF($J29=AE$2,"x","")
B30: K01 | C30: Mock construction of full project in Cardboard only - all parts represented | D30: Marking Scheme | E30: Construction | G30: Partners present in Lab | H30: Build | I30: PH1 | J30: 3 | M30: =N30/6 -> 1 | N30: 6 | Q30: =IF($J30=Q$2,"x","") | S30: x | X30: =IF($J30=X$2,"x","")
B31: A00 | C31: Week 04 | J31: 4 | Q31: =IF($J31=Q$2,"x","") | T31: x | X31: =IF($J31=X$2,"x","")
B32: A03 | C32: Team Status: PM1 to lead demos | D32: Marking Scheme | E32: Briefing | G32: Partners present in Lab | H32: Demo | I32: PH1 | J32: 4 | M32: =N32/6 -> 2 | N32: 12 | Q32: =IF($J32=Q$2,"x","") | T32: x | X32: =IF($J32=X$2,"x","")
B33: F01 | C33: Demo: Multiple items | D33: Marking Scheme | E33: Demonstration | G33: Partners present in Lab | H33: Demo | I33: PH1 | J33: 4 | M33: =N33/6 -> 1 | N33: 6 | Q33: =IF($J33=Q$2,"x","") | T33: x | X33: =IF($J33=X$2,"x","")
B34: F01-a | C34: Demo: Coding IDE installed with Extensions - (PlatformIO, etc) | D34: Project Software - Code & IoT | G34: Demonstration in Lab | H34: Demo | I34: PH1 | J34: 4 | K34: 46045 | Q34: =IF($J34=Q$2,"x","") | R34: =IF($J34=R$2,"x","") | S34: =IF($J34=S$2,"x","") | T34: =IF($J34=T$2,"x","") -> x | U34: =IF($J34=U$2,"x","") | V34: =IF($J34=V$2,"x","") | W34: =IF($J34=W$2,"x","") | X34: =IF($J34=X$2,"x","") | ... AE34: =IF($J34=AE$2,"x","")
B35: F01-b | C35: Demo: Show GitHub setup for each member's account | D35: Project Software - Code & IoT | G35: Demonstration in Lab | H35: Demo | I35: PH1 | J35: 4 | K35: 46045 | Q35: =IF($J35=Q$2,"x","") | R35: =IF($J35=R$2,"x","") | S35: =IF($J35=S$2,"x","") | T35: =IF($J35=T$2,"x","") -> x | U35: =IF($J35=U$2,"x","") | V35: =IF($J35=V$2,"x","") | W35: =IF($J35=W$2,"x","") | X35: =IF($J35=X$2,"x","") | ... AE35: =IF($J35=AE$2,"x","")
B36: F01-c | C36: On Hand: MCU installed on a breadboard - keep in a small TPJ box | D36: Project Hardware - Elec, Mech | G36: Demonstration in Lab | H36: Demo | I36: PH1 | J36: 4 | K36: 46052 | Q36: =IF($J36=Q$2,"x","") | R36: =IF($J36=R$2,"x","") | S36: =IF($J36=S$2,"x","") | T36: =IF($J36=T$2,"x","") -> x | U36: =IF($J36=U$2,"x","") | V36: =IF($J36=V$2,"x","") | W36: =IF($J36=W$2,"x","") | X36: =IF($J36=X$2,"x","") | ... AE36: =IF($J36=AE$2,"x","")
B37: F01-d | C37: On Hand: Some Inputs & Outputs, Test Wires, Breadboards, in a box | D37: Project Hardware - Elec, Mech | G37: Demonstration in Lab | H37: Demo | I37: PH1 | J37: 4 | K37: 46052 | Q37: =IF($J37=Q$2,"x","") | R37: =IF($J37=R$2,"x","") | S37: =IF($J37=S$2,"x","") | T37: =IF($J37=T$2,"x","") -> x | U37: =IF($J37=U$2,"x","") | V37: =IF($J37=V$2,"x","") | W37: =IF($J37=W$2,"x","") | X37: =IF($J37=X$2,"x","") | ... AE37: =IF($J37=AE$2,"x","")
B38: F01-e | C38: §15B - Project Electrical Wiring Diagram - use Fusion to export .jpg | D38: Technical Report | G38: Intended: Technical Report, section §15B | H38: File | I38: PH1 | J38: 4 | K38: 46052 | Q38: =IF($J38=Q$2,"x","") | R38: =IF($J38=R$2,"x","") | S38: =IF($J38=S$2,"x","") | T38: =IF($J38=T$2,"x","") -> x | U38: =IF($J38=U$2,"x","") | V38: =IF($J38=V$2,"x","") | W38: =IF($J38=W$2,"x","") | X38: =IF($J38=X$2,"x","") | ... AE38: =IF($J38=AE$2,"x","")
B39: F01-f | C39: §15D - Mechanical Diagram - use CAD to export .jpg | D39: Technical Report | G39: Intended: Technical Report, section §15D | H39: File | I39: PH1 | J39: 4 | K39: 46052 | Q39: =IF($J39=Q$2,"x","") | R39: =IF($J39=R$2,"x","") | S39: =IF($J39=S$2,"x","") | T39: =IF($J39=T$2,"x","") -> x | U39: =IF($J39=U$2,"x","") | V39: =IF($J39=V$2,"x","") | W39: =IF($J39=W$2,"x","") | X39: =IF($J39=X$2,"x","") | ... AE39: =IF($J39=AE$2,"x","")
B40: F01-g | C40: §15E - IoT Dashboard page layout design - use Visio or yEd to export .jpg | D40: Technical Report | G40: Intended: Technical Report, section §15E | H40: File | I40: PH1 | J40: 4 | K40: 46052 | Q40: =IF($J40=Q$2,"x","") | R40: =IF($J40=R$2,"x","") | S40: =IF($J40=S$2,"x","") | T40: =IF($J40=T$2,"x","") -> x | U40: =IF($J40=U$2,"x","") | V40: =IF($J40=V$2,"x","") | W40: =IF($J40=W$2,"x","") | X40: =IF($J40=X$2,"x","") | ... AE40: =IF($J40=AE$2,"x","")
B41: A00 | C41: Week 05 | J41: 5 | Q41: =IF($J41=Q$2,"x","") | U41: x | X41: =IF($J41=X$2,"x","")
...

Sheet PH1 Marking Notes
B2: WBS | C2: ='Schedule and Progress'!C2 -> Description of Tasks - TPJ655 | D2: Format | E2: Instructions to Complete Item Level 4 Rating (For Best Marks) | F2: Marks To Be Deducted Under These Conditions Level 1, 2, and 3 Ratings | G2: Comments, as needed
B4: Week 3 | C4: FALSE
B5: B01 | C5: =_xlfn.XLOOKUP($B5,'Schedule and Progress'!$B$2:$B$187,'Schedule and Progress'!$C$2:$C$187) -> Project Charter - include updates to all tabs (esp. Contract, Budget, BOM) | D5: =_xlfn.XLOOKUP($B5,'Schedule and Progress'!$B$2:$B$187,'Schedule and Progress'!$F$2:$F$187) -> Dropbox1 | E5: Team saved a copy of this Excel file and uploaded it to the dropbox. All student tabs (Summary, latest Contract, Budget, and BOM) are up to date with meaningful information. The proposed project parameters matches the expectations for the course. | F5: Missing information or the required parts are incomplete. Insufficient information to make an informed decision on the approval for the project.
B7: B01-b | C7: =_xlfn.XLOOKUP($B7,'Schedule and Progress'!$B$2:$B$187,'Schedule and Progress'!$C$2:$C$187) -> Confirm: MCU, identify number of GPIO pins available | D7: =_xlfn.XLOOKUP($B7,'Schedule and Progress'!$B$2:$B$187,'Schedule and Progress'!$F$2:$F$187) -> 0 | E7: Team has chosen an MCU based upon cost analysis, power consumption, and other requirements of the project. Choice is supported with the number and types of GPIO pins per electronic device and consideration of any protocols (eg. PWM, SPI, I2C, etc.). | F7: Team has chosen a PLC or an MCU that will be unsuitable as a primary MCU for the project, or has not provided justification for its selection. For example: Arduino Uno, Duo, Mega, RPi Pico, M5Stamp, FRDM-K64F, etc. Note: This choice will not be approved.
B9: B01-d | C9: =_xlfn.XLOOKUP($B9,'Schedule and Progress'!$B$2:$B$187,'Schedule and Progress'!$C$2:$C$187) -> Include clear purpose of IoT dashboard integration | D9: =_xlfn.XLOOKUP($B9,'Schedule and Progress'!$B$2:$B$187,'Schedule and Progress'!$F$2:$F$187) -> 0 | E9: Team has chosen to create the dashboard from scratch with full control over the code and graphical user interface (GUI). Example: If using an ESP32 as primary MCU, the Team has likely chosen HTML or equivalent coding for this dashboard. A plan for improved security is outlined in details. | F9: Team has incorrectly chosen to use an existing cloud platform solution (such as Blynk, Ubidots, Adafruit.io, Thingspeak, Thinger.io, or similar) that does not require code or is otherwise unsuitable. Note: This choice will not be approved.
B11: C01 | C11: =_xlfn.XLOOKUP($B11,'Schedule and Progress'!$B$2:$B$187,'Schedule and Progress'!$C$2:$C$187) -> Presentation: full project overview - include audio in .pptx | D11: =_xlfn.XLOOKUP($B11,'Schedule and Progress'!$B$2:$B$187,'Schedule and Progress'!$F$2:$F$187) -> Dropbox1 | E11: Team provided a PPTX and a MP4 version of their presentation files. The presentation does not exceed 12 minutes. The template was used appropriately and completely. Sufficient information is provided by the students (along with their Project Charter) both in text and in voice-over details to make a decision on the approval status of the project. Both team members participated in the generation of the video content, and both are engaging to the audience in their explanations, explaining complex topics but in straightforward language. | F11: Incomplete or insufficient data or research has been provided. Use of AI to write several sections or provide notes may be suspected. Purpose of project is lacking depth. Project may be found easily online as DIY projects and no attempt is made in the Proposal to differentiate from them.
B13: C01-c | C13: =_xlfn.XLOOKUP($B13,'Schedule and Progress'!$B$2:$B$187,'Schedule and Progress'!$C$2:$C$187) -> List: Purpose of each input, each output | D13: =_xlfn.XLOOKUP($B13,'Schedule and Progress'!$B$2:$B$187,'Schedule and Progress'!$F$2:$F$187) -> 0 | E13: A complete list of all electronics are provided, sorted by type of input and output, and formatted for easy reading. Expecting 8 or more inputs and outputs. Clear, descriptive, and useful purpose for each device has been provided. | F13: Simple devices are included in the count -- pushbuttons and LEDs should be included on the list but only for reference. Incomplete list, complexity is too simple for TPJ6. Missing important details about the purpose of devices.
B15: C01-e | C15: =_xlfn.XLOOKUP($B15,'Schedule and Progress'!$B$2:$B$187,'Schedule and Progress'!$C$2:$C$187) -> System Block Diagram (SBD) - use Visio or yEd to export .jpg | D15: =_xlfn.XLOOKUP($B15,'Schedule and Progress'!$B$2:$B$187,'Schedule and Progress'!$F$2:$F$187) -> 0 | E15: Use software (yEd or Visio) to create the basic structure (Inputs, MCU, Outputs) and save as an image. The scope of the inputs and outputs is of appropriate complexity. Its format follows the structure requested in TPJ class. | F15: Drawn by hand, shared as photograph, errors, incomplete, did not follow instructions in class. Scope may be too simple for expected level. Expecting 8 or more inputs & outputs, not a Raspberry Pi, and something that isn't easily found on Instructables or similar websites.
B17: C01-f | C17: =_xlfn.XLOOKUP($B17,'Schedule and Progress'!$B$2:$B$187,'Schedule and Progress'!$C$2:$C$187) -> Mechanical Drawing of entire project | D17: =_xlfn.XLOOKUP($B17,'Schedule and Progress'!$B$2:$B$187,'Schedule and Progress'!$F$2:$F$187) -> 0 | E17: Image for this submission can be either handdrawn or sketched using CAD or digital drawing tools. Clearly shows proportions of overall vision. Design may change but this version is a great basis for planning. | F17: Unclear proportions, submitted as standalone file (not inside the Deliverables file). Difficult to envision what will be the final product. AI image provided but not identified as such with citation.
B19: C01-g | C19: =_xlfn.XLOOKUP($B19,'Schedule and Progress'!$B$2:$B$187,'Schedule and Progress'!$C$2:$C$187) -> Introduction - introduce project, why this idea, hook | D19: =_xlfn.XLOOKUP($B19,'Schedule and Progress'!$B$2:$B$187,'Schedule and Progress'!$F$2:$F$187) -> 0 | E19: Team has written a meaningful complete draft of their introduction to the Technical Report. Students have effectively answered the Why, Who, When, Where, What questions that the reader will have at the start, and it is done in an interesting and engaging manner, with a voice that is authentic to the team members. Research claims (usually about the Why) are supported with proper references. | F19: Missing information or lack of personalization of this section. Team has not yet connected with the reader or explained their motivations for working on the project or why it is important. Citations may be incomplete and must be fixed. Use of AI to write the section may be suspected.
B21: C01-h | C21: =_xlfn.XLOOKUP($B21,'Schedule and Progress'!$B$2:$B$187,'Schedule and Progress'!$C$2:$C$187) -> Start Background Research - find 3 similar projects, discuss | D21: =_xlfn.XLOOKUP($B21,'Schedule and Progress'!$B$2:$B$187,'Schedule and Progress'!$F$2:$F$187) -> 0 | E21: Team has provided a substantially researched Technical Report section on the related research appropriate to their project idea. Three or more projects from industry or DIY project websites have been found, a cited image is provided, and each are discussed in detail with respect to the similarities and differences. Web URLs and proper referencing of each project is provided. | F21: Team has provided only very simple links to projects that resemble their project idea, or the linked projects are not effectively similar (i.e. only weakly linked). Students have not done substantial research at this point so the similarities and differences are only based on simple observations. Citation may be incomplete and must be fixed. Use of AI to write the section may be suspected.
B24: Week 4 | C24: FALSE
B25: F01-a | C25: =_xlfn.XLOOKUP($B25,'Schedule and Progress'!$B$2:$B$187,'Schedule and Progress'!$C$2:$C$187) -> Demo: Coding IDE installed with Extensions - (PlatformIO, etc) | D25: =_xlfn.XLOOKUP($B25,'Schedule and Progress'!$B$2:$B$187,'Schedule and Progress'!$F$2:$F$187) -> 0 | E25: While in the lab, PM1/2 gives a live demonstration of this item. Example: Team shows VS Code with PlatformIO installed. Both students are aware of the software setup. | F25: A partial walkthrough is provided in the lab, or the team uploads a video to the next Dropbox (late).
B27: F01-e | C27: =_xlfn.XLOOKUP($B27,'Schedule and Progress'!$B$2:$B$187,'Schedule and Progress'!$C$2:$C$187) -> §15B - Project Electrical Wiring Diagram - use Fusion to export .jpg | D27: =_xlfn.XLOOKUP($B27,'Schedule and Progress'!$B$2:$B$187,'Schedule and Progress'!$F$2:$F$187) -> 0 | E27: First draft available. Pinouts are indicated on the MCU, power layout is present, and all parts have associated passive components identified (resistors, caps, etc.). Ideally the drawing is completed with Fusion, but may be handdrawn at this point. | F27: Unclear elements like incomplete portions, inappropriate choices to the MCU pins, missing passive components (like resistors for LEDs), or other anomalies. Note that an AI-generated schematic is not acceptable.
B30: Week 5 | C30: FALSE
B31: G01 | C31: =_xlfn.XLOOKUP($B31,'Schedule and Progress'!$B$2:$B$187,'Schedule and Progress'!$C$2:$C$187) -> Technical Report Draft - full shell file with TOC, TOF, header/footer, diagrams | D31: =_xlfn.XLOOKUP($B31,'Schedule and Progress'!$B$2:$B$187,'Schedule and Progress'!$F$2:$F$187) -> Dropbox2 | E31: Supporting evidence is provided and cited. All previous sections and those listed for this week are included as complete as possible, and remaining sections have their own page and titles ready for the next revision. The TOC and TOF are set up now. Students have clearly read the help file and are following its advice. Simple and clear outlines of the project and how it looks are included, even if they will be updated at a later date. | F31: Incomplete missing sections or parts. Missing diagrams. Shell does not follow expectations from the help file.
B33: G01-e | C33: =_xlfn.XLOOKUP($B33,'Schedule and Progress'!$B$2:$B$187,'Schedule and Progress'!$C$2:$C$187) -> §05. Background Research & Development (fully developed section now) | D33: =_xlfn.XLOOKUP($B33,'Schedule and Progress'!$B$2:$B$187,'Schedule and Progress'!$F$2:$F$187) -> 0 | E33: Team has updated all citations according to the current state of the project. The references to all images, information sources, and quotations are all cited and refer to real references in Section 14 References. The format of the in line citations and the References section is college-level appropriate, either styled in MLA or APA format. | F33: Team has provided only very simple links to projects that resemble their project idea, or the linked projects are not effectively similar (i.e. only weakly linked). Students have not done substantial research at this point so the similarities and differences are only based on simple observations. Citation may be incomplete and must be fixed. Use of AI to write the section may be suspected.
B35: G01-f | C35: =_xlfn.XLOOKUP($B35,'Schedule and Progress'!$B$2:$B$187,'Schedule and Progress'!$C$2:$C$187) -> §07. System Design and Layout - SBD, related flowcharts, descriptions | D35: =_xlfn.XLOOKUP($B35,'Schedule and Progress'!$B$2:$B$187,'Schedule and Progress'!$F$2:$F$187) -> 0 | E35: This section is full of project related images. These images will appear in the Table of Figures at the beginning of the report. Team has updated images according to the current state of the project. The System Block Diagram follows the layout suggested in class, flowchart shows the coding processes and decisions of the program, and some descriptions are added for clarity. | F35: Images not captioned, not shown in TOF. Current state of project is not reflected in these images. SBD still requires updating in its formating. Some images missing or incomplete.
B37: G01-g | C37: =_xlfn.XLOOKUP($B37,'Schedule and Progress'!$B$2:$B$187,'Schedule and Progress'!$C$2:$C$187) -> §08. Hardware Components & Specifications - with cited pics | D37: =_xlfn.XLOOKUP($B37,'Schedule and Progress'!$B$2:$B$187,'Schedule and Progress'!$F$2:$F$187) -> 0 | E37: This section is full of project related images, specifically all the electronics hardware devices. Each of these images will appear in the Table of Figures at the beginning of the report. Team has updated images according to the current state of the project. Likely a tabular format with clear descriptions and cited electrical specifications. | F37: Images not captioned, not shown in TOF. Current state of project is not reflected in these images. Formating of images are incorrect -- for example, skewed aspect ratio, items still within bags, pictures do not show item clearly. Some images missing or incomplete.
B39: G01-h | C39: =_xlfn.XLOOKUP($B39,'Schedule and Progress'!$B$2:$B$187,'Schedule and Progress'!$C$2:$C$187) -> §14. References - MLA or APA format preferred | D39: =_xlfn.XLOOKUP($B39,'Schedule and Progress'!$B$2:$B$187,'Schedule and Progress'!$F$2:$F$187) -> 0 | E39: Team has updated all citations according to the current state of the project. The references to all images, information sources, and quotations are all listed in this section. The format of the in line citations and the References section is college-level appropriate, either styled in MLA or APA format. | F39: Team has supplied a list of URLs, fake references, or substantially incomplete information about references. This section must be fixed.
B41: H01 | C41: =_xlfn.XLOOKUP($B41,'Schedule and Progress'!$B$2:$B$187,'Schedule and Progress'!$C$2:$C$187) -> Presentation Draft - full shell file with basic layout and intro updated | D41: =_xlfn.XLOOKUP($B41,'Schedule and Progress'!$B$2:$B$187,'Schedule and Progress'!$F$2:$F$187) -> Dropbox2 | E41: Draft PPTX file set up according to the expectations described in the help file. Team has filled in as many sections with details as available up to this point in the semester. All headings and expected slides are present. Team has paid attention to readability and flow of their slidedeck. At least one slide contains a voiceover recording. Both students have contributed to the development of this file. | F41: Incomplete or insufficient data or research has been provided. Use of AI to write several sections or provide notes may be suspected. Sections expected to be completed are not yet updated.

Sheet PH2 Marking Notes
B2: WBS | C2: ='Schedule and Progress'!C2 -> Description of Tasks - TPJ655 | D2: Format | E2: Instructions to Complete Item Level 4 Rating (For Best Marks) | F2: Marks To Be Deducted Under These Conditions Level 1, 2, and 3 Ratings | G2: Comments, as needed
B4: Week 6 | C4: FALSE
B5: E02-d | C5: =_xlfn.XLOOKUP($B5,'Schedule and Progress'!$B$2:$B$187,'Schedule and Progress'!$C$2:$C$187) -> Bring in physical paper of PCB printed layout, version 1, 100% scale | D5: =_xlfn.XLOOKUP($B5,'Schedule and Progress'!$B$2:$B$187,'Schedule and Progress'!$F$2:$F$187) -> 0 | E5: Students have printed a 1:1 scale printout on paper of the current PCB Layout of their Rev 1 board. Parts that will be connected to the PCB or PCBs in their project are clearly labelled and the design(s) are easy to read at a glance. The layout is not messy. The design is not simply a connector board either (like a breakout board). The team has worked on making an efficiently-sized PCB and tried to make it single-sided wherever possible. | F5: Layout is messy or unclear. Layout looks like a breakout module for the MCU only. The size of the board is too large for the number and spacing of components in the design. Mounting holes are not present. Team has not clearly thought about the location of the ports, connectors, headers, terminals, etc.
B8: Week 7 | C8: FALSE
B9: E03-c | C9: =_xlfn.XLOOKUP($B9,'Schedule and Progress'!$B$2:$B$187,'Schedule and Progress'!$C$2:$C$187) -> Demo Live: Show instructor 3D model, get feedback before printing | D9: =_xlfn.XLOOKUP($B9,'Schedule and Progress'!$B$2:$B$187,'Schedule and Progress'!$F$2:$F$187) -> 0 | E9: The 3D design is thoughtfully arranged with minimal size for the application, and does not exceed the printer lab's limitations in volume or size. The 3D design is not just a design from the internet but has been significantly modified or drawn by the team. The team will show the model (likely using the Bambu Studio from MyApps) and receive feedback on the slicing of the object(s). Both students are aware of the setup. | F9: Incomplete, disorganized, unclear, or missing items.
B11: G02-b | C11: =_xlfn.XLOOKUP($B11,'Schedule and Progress'!$B$2:$B$187,'Schedule and Progress'!$C$2:$C$187) -> §01. Title Page | D11: =_xlfn.XLOOKUP($B11,'Schedule and Progress'!$B$2:$B$187,'Schedule and Progress'!$F$2:$F$187) -> 0 | E11: Proper title page information is provided, including any images with captions and details about the students and course. The image(s) will appear in the Table of Figures at the beginning of the report. | F11: Incomplete, disorganized, unclear, or missing items. Spelling errors. Missing Group number.
B13: G02-c | C13: =_xlfn.XLOOKUP($B13,'Schedule and Progress'!$B$2:$B$187,'Schedule and Progress'!$C$2:$C$187) -> §03. Table of Contents (TOC) and Table of Figures (TOF) | D13: =_xlfn.XLOOKUP($B13,'Schedule and Progress'!$B$2:$B$187,'Schedule and Progress'!$F$2:$F$187) -> 0 | E13: These are provided in their entirety according to all the titles in the paper, including all major headings of chapters in the TOC and all captions for images in the TOF. | F13: Incomplete, disorganized, unclear, or missing items.
B15: G02-d | C15: =_xlfn.XLOOKUP($B15,'Schedule and Progress'!$B$2:$B$187,'Schedule and Progress'!$C$2:$C$187) -> §06. System Functional Features & Specifications | D15: =_xlfn.XLOOKUP($B15,'Schedule and Progress'!$B$2:$B$187,'Schedule and Progress'!$F$2:$F$187) -> 0 | E15: Includes all images with captions and descriptions of the project as a system clearly explained. Parts of this section may be in tabular form to collect together the overall information and functional specifications. The images are captioned and appear in the Table of Figures at the beginning of the report. All information, research, and images are appropriately cited, both in line and in the References section. | F15: Incomplete, disorganized, unclear, or missing items.
B17: G02-e | C17: =_xlfn.XLOOKUP($B17,'Schedule and Progress'!$B$2:$B$187,'Schedule and Progress'!$C$2:$C$187) -> §10. Product Operating Instructions | D17: =_xlfn.XLOOKUP($B17,'Schedule and Progress'!$B$2:$B$187,'Schedule and Progress'!$F$2:$F$187) -> 0 | E17: Includes relevant images with captions and descriptions of moving parts or interactions with the hardware clearly explained. This section may read like a recipe in terms of how the user will follow its directions. The images will appear in the Table of Figures at the beginning of the report. Team has updated all images according to the current state of the project. All information, research, and images are appropriately cited, both in line and in the References section. | F17: Incomplete, disorganized, unclear, or missing items.
B19: G02-g | C19: =_xlfn.XLOOKUP($B19,'Schedule and Progress'!$B$2:$B$187,'Schedule and Progress'!$C$2:$C$187) -> §15B - Schematic Diagrams of System & PCBs (all) - use Fusion to export .jpg | D19: =_xlfn.XLOOKUP($B19,'Schedule and Progress'!$B$2:$B$187,'Schedule and Progress'!$F$2:$F$187) -> 0 | E19: Schematics are clean, clear images and thoughtfully arranged on the pages, as well as their content is thoughtfully arranged with minimal crossing nets. Custom parts were either drawn by the students or installed from appropriate sources (eg. SnapEDA or DigiKey). Citations are provided. The Fusion file is included in the submission. | F19: Incomplete, disorganized, unclear, or missing items.
B21: G02-h | C21: =_xlfn.XLOOKUP($B21,'Schedule and Progress'!$B$2:$B$187,'Schedule and Progress'!$C$2:$C$187) -> §15C - PCB Layout Design Diagram (all) - use Fusion to export .jpg | D21: =_xlfn.XLOOKUP($B21,'Schedule and Progress'!$B$2:$B$187,'Schedule and Progress'!$F$2:$F$187) -> 0 | E21: The PCB Layout images are clean, clear images, not stretched or modified, and fit well on the page. The layout of the PCBs make sense for their application. The team has included a 3D model from a top corner perspective of the PCB layout in addition to providing the 2D top and bottom layouts. The team has also included space in this section of the report to have the photos of the top and bottom PCB, once it is fully soldered later in the semester. The Fusion file is included in the submission. If a connector will be installed on the board, it has all pins for the device in a row in their correct ordering (eg. Vcc, DI, DO, GND). | F21: Incomplete, disorganized, unclear, or missing items. Possibly oversized or double-sided when the design could have been single-sided with a little more planning on the placement of components.
B23: G02-i | C23: =_xlfn.XLOOKUP($B23,'Schedule and Progress'!$B$2:$B$187,'Schedule and Progress'!$C$2:$C$187) -> §15F - Coding Flowchart - use Visio or yEd to export .jpg | D23: =_xlfn.XLOOKUP($B23,'Schedule and Progress'!$B$2:$B$187,'Schedule and Progress'!$F$2:$F$187) -> 0 | E23: A simple but clear outline of the decision tree and full program's application covering the entire project has been completed, with multiple pages where needed. Readability is high. Students are using either Visio or yEd to generate the original image. Citations are provided. | F23: Coding flowchart created in Paint, or a similar low resolution program. The diagram may be incomplete or only a rough digital sketch of the project. Readability may be suffering from lack of sufficient colour contrast (eg. black text on white bkgd) or simplicity in layout. Large diagrams use tiny fonts, instead of increasing the font size and using multiple diagrams to show with clarity.
B26: Week 8 | C26: FALSE
C27: Additional Notes | E27: No classes or labs during Study Week. Students are expected to continue working on their project in their own time. Open Labs are available on campus.
B29: Week 9 | C29: FALSE
B30: E04-a | C30: =_xlfn.XLOOKUP($B30,'Schedule and Progress'!$B$2:$B$187,'Schedule and Progress'!$C$2:$C$187) -> Bring in physical PCB, version 1 or higher | D30: =_xlfn.XLOOKUP($B30,'Schedule and Progress'!$B$2:$B$187,'Schedule and Progress'!$F$2:$F$187) -> 0 | E30: While in the lab, Team shows that one or more PCBs is printed and on hand. Another version may be required, and the Team understands there are only two weeks left to order the final versions. | F30: Missing.
B33: Week 10 | C33: FALSE
B34: B03 | C34: =_xlfn.XLOOKUP($B34,'Schedule and Progress'!$B$2:$B$187,'Schedule and Progress'!$C$2:$C$187) -> Project Charter - include updates to all tabs, interim version | D34: =_xlfn.XLOOKUP($B34,'Schedule and Progress'!$B$2:$B$187,'Schedule and Progress'!$F$2:$F$187) -> Dropbox4 | E34: Team saved a copy of this Excel file and uploaded it to the dropbox. All student tabs (Summary, latest Contract, Budget, and BOM) are up to date with meaningful information. The proposed project parameters matches the expectations for the course. | F34: Missing information or the required parts are incomplete.
B36: G03-b | C36: =_xlfn.XLOOKUP($B36,'Schedule and Progress'!$B$2:$B$187,'Schedule and Progress'!$C$2:$C$187) -> §09. Theory of Operation | D36: =_xlfn.XLOOKUP($B36,'Schedule and Progress'!$B$2:$B$187,'Schedule and Progress'!$F$2:$F$187) -> 0 | E36: This section includes all images with captions and interesting or innovative parts of the project fully researched and explained. The images will appear in the Table of Figures at the beginning of the report. Team has updated all images according to the current state of the project. All information, research, and images are appropriately cited, both in line and in the References section. | F36: Incomplete, disorganized, unclear, or missing items. References not provided -- must be fixed.
B38: G03-c | C38: =_xlfn.XLOOKUP($B38,'Schedule and Progress'!$B$2:$B$187,'Schedule and Progress'!$C$2:$C$187) -> §11. Maintenance Requirements | D38: =_xlfn.XLOOKUP($B38,'Schedule and Progress'!$B$2:$B$187,'Schedule and Progress'!$F$2:$F$187) -> 0 | E38: This section includes all images with captions and descriptions of user interaction with the project to keep it clean and well maintained clearly explained. The images will appear in the Table of Figures at the beginning of the report. Team has updated all images according to the current state of the project. All information, research, and images are appropriately cited, both in line and in the References section. | F38: Incomplete, disorganized, unclear, or missing items.
B40: G03-d | C40: =_xlfn.XLOOKUP($B40,'Schedule and Progress'!$B$2:$B$187,'Schedule and Progress'!$C$2:$C$187) -> §15E - IoT Dashboard - final screenshots as .jpg | D40: =_xlfn.XLOOKUP($B40,'Schedule and Progress'!$B$2:$B$187,'Schedule and Progress'!$F$2:$F$187) -> 0 | E40: The IoT dashboard images are numerous, clean, clear images and thoughtfully arranged on the pages, as well as their content is thoughtfully arranged with minimal confusion in readability. Citations are provided. Context is provided. | F40: Incomplete, disorganized, unclear, or missing items.

Sheet PH3 Marking Notes
B2: WBS | C2: ='Schedule and Progress'!C2 -> Description of Tasks - TPJ655 | D2: Format | E2: Instructions to Complete Item Level 4 Rating (For Best Marks) | F2: Marks To Be Deducted Under These Conditions Level 1, 2, and 3 Ratings | G2: Comments, as needed
B4: Week 11 | C4: FALSE
B5: E06-a | C5: =_xlfn.XLOOKUP($B5,'Schedule and Progress'!$B$2:$B$187,'Schedule and Progress'!$C$2:$C$187) -> On Hand: All materials for final build - previous, plus all mechanicals | D5: =_xlfn.XLOOKUP($B5,'Schedule and Progress'!$B$2:$B$187,'Schedule and Progress'!$F$2:$F$187) -> 0 | E5: Team has all build materials for the final prototype on the workstation table. This includes a PCB, all the electronics, the 3D print, and the fasteners and other materials (wood? etc.) required to build the final project. | F5: Missing or incomplete parts.
B7: E06-d | C7: =_xlfn.XLOOKUP($B7,'Schedule and Progress'!$B$2:$B$187,'Schedule and Progress'!$C$2:$C$187) -> Install one 3D Model on project build (minimum) | D7: =_xlfn.XLOOKUP($B7,'Schedule and Progress'!$B$2:$B$187,'Schedule and Progress'!$F$2:$F$187) -> 0 | E7: Team shows their built project has one or more 3D prints installed, designed fully by the Team or substantially modified by the team and fully referenced. | F7: Missing or incomplete.
B9: F07-a | C9: =_xlfn.XLOOKUP($B9,'Schedule and Progress'!$B$2:$B$187,'Schedule and Progress'!$C$2:$C$187) -> Demo Live: Current Full Code of Project - show in the IDE | D9: =_xlfn.XLOOKUP($B9,'Schedule and Progress'!$B$2:$B$187,'Schedule and Progress'!$F$2:$F$187) -> 0 | E9: Team shows IDE (eg. VS Code) file structure and setup, then spends 3-5 minutes explaining high level decision tree of entire program, in sections. Both students are aware of the software and hardware setup. | F9: Missing or incomplete. Missing annotations and full references. One main file contains all code.
H10: FALSE
B12: Week 12 | C12: FALSE
B13: E07-a | C13: =_xlfn.XLOOKUP($B13,'Schedule and Progress'!$B$2:$B$187,'Schedule and Progress'!$C$2:$C$187) -> Confirm all hardware is installed with appropriate connections to PCB | D13: =_xlfn.XLOOKUP($B13,'Schedule and Progress'!$B$2:$B$187,'Schedule and Progress'!$F$2:$F$187) -> 0 | E13: Team shows their built project built prototype on hand. It has 80% or higher working electronics fully installed, one or more 3D prints installed, as well one or more PCBs is printed, soldered, and installed on the prototype. (Another PCB version may be required, and the Team understands this is the last week to order any new boards.) It is clear that all temporary or flimsy build materials have been removed or replaced. | F13: Temporary or flimsy build materials are still present. Build looks substantially incomplete. Missing components like the 3D part or PCB, or it's not soldered and installed as expected.
B15: F08-a | C15: =_xlfn.XLOOKUP($B15,'Schedule and Progress'!$B$2:$B$187,'Schedule and Progress'!$C$2:$C$187) -> Demo Live: Upload code to MCU using IDE | D15: =_xlfn.XLOOKUP($B15,'Schedule and Progress'!$B$2:$B$187,'Schedule and Progress'!$F$2:$F$187) -> 0 | E15: Team gives a live demonstration of this item. Example: Member shows VS Code file structure and setup, then spends 3-5 minutes explaining high level decision tree of entire program, in sections. Both students are aware of the software and hardware setup. | F15: Missing or incomplete.
B17: G04-e | C17: =_xlfn.XLOOKUP($B17,'Schedule and Progress'!$B$2:$B$187,'Schedule and Progress'!$C$2:$C$187) -> §02. Abstract | D17: =_xlfn.XLOOKUP($B17,'Schedule and Progress'!$B$2:$B$187,'Schedule and Progress'!$F$2:$F$187) -> 0 | E17: This section includes a high level overview of the purpose of the project, the students' process, the results, and which results specifically provide evidence for success. This is a short section, written at the end of the project's completion because of the nature of what it should contain. This section shows no signs of AI influence in its wording. | F17: Incomplete, disorganized, unclear, or missing items.
H18: FALSE
B19: G04-f | C19: =_xlfn.XLOOKUP($B19,'Schedule and Progress'!$B$2:$B$187,'Schedule and Progress'!$C$2:$C$187) -> §12. Future Improvements | D19: =_xlfn.XLOOKUP($B19,'Schedule and Progress'!$B$2:$B$187,'Schedule and Progress'!$F$2:$F$187) -> 0 | E19: This section includes all images with captions and descriptions of future improvements clearly explained. Parts of this section may be in tabular form, and students do have permission to create images using AI generators if they choose (or sketch or CAD them). The images are captioned and appear in the Table of Figures at the beginning of the report. All information, research, and images are appropriately cited, both in line and in the References section. | F19: Incomplete, disorganized, unclear, or missing items.
B21: G04-g | C21: =_xlfn.XLOOKUP($B21,'Schedule and Progress'!$B$2:$B$187,'Schedule and Progress'!$C$2:$C$187) -> §13. Conclusions: Challenges, Successes, Evidential Accuracy | D21: =_xlfn.XLOOKUP($B21,'Schedule and Progress'!$B$2:$B$187,'Schedule and Progress'!$F$2:$F$187) -> 0 | E21: This section includes a high level overview of the challenges the team faced, what turned out successful, and supporting evidence to prove the success. For example, if a sensor is able to measure temperature, to what degree does it accurately read the temperature? (What is it measured against?) This is likely a substantial section, written at the end of the project's completion because of the nature of what it should contain. This section shows little to no signs of AI influence in its wording. | F21: Incomplete, disorganized, unclear, or missing items.
B23: G04-i | C23: =_xlfn.XLOOKUP($B23,'Schedule and Progress'!$B$2:$B$187,'Schedule and Progress'!$C$2:$C$187) -> §15F. Full Project Software Code - must be text format, fully annotated | D23: =_xlfn.XLOOKUP($B23,'Schedule and Progress'!$B$2:$B$187,'Schedule and Progress'!$F$2:$F$187) -> 0 | E23: The full project software code is updated in the Technical Report Section 15 Appendix F. Team has updated all citations according to the current state of the project. The project code is easy to read because it is in a 2-row table: the top row is the name of the file; the bottom, the indented code. Annotations are college-level appropriate. | F23: Missing or incomplete. Missing annotations and full references.
B26: Week 13 | C26: FALSE
B27: A11 | C27: =_xlfn.XLOOKUP($B27,'Schedule and Progress'!$B$2:$B$187,'Schedule and Progress'!$C$2:$C$187) -> Team Status | D27: =_xlfn.XLOOKUP($B27,'Schedule and Progress'!$B$2:$B$187,'Schedule and Progress'!$F$2:$F$187) -> 0 | E27: Team confirms they have updated all photos used throughout the Technical Report. In particular, different viewpoints of the project are included, such as the inside of the enclosure, the PCB top and bottom after soldering and after cable installation, and all pages of the IoT dashboard. The images all appear in the Table of Figures at the beginning of the report and are appropriately cited. | F27: Student have not started filming Final Demonstration yet because the build is still incomplete.
B29: F09-a | C29: =_xlfn.XLOOKUP($B29,'Schedule and Progress'!$B$2:$B$187,'Schedule and Progress'!$C$2:$C$187) -> Demo Live: Final Version of Software walk-through - show in the IDE | D29: =_xlfn.XLOOKUP($B29,'Schedule and Progress'!$B$2:$B$187,'Schedule and Progress'!$F$2:$F$187) -> 0 | E29: Team shows IDE (eg. VS Code) file structure and setup, then spends 3-5 minutes explaining high level decision tree of entire program, in sections. Both students are aware of the software and hardware setup. | F29: Missing or incomplete. Missing annotations and full references. One main file contains all code.
B32: Week 14 | C32: FALSE
B33: A12 | C33: =_xlfn.XLOOKUP($B33,'Schedule and Progress'!$B$2:$B$194,'Schedule and Progress'!$C$2:$C$194) -> Team Status | D33: =_xlfn.XLOOKUP($B33,'Schedule and Progress'!$B$2:$B$187,'Schedule and Progress'!$F$2:$F$187) -> 0 | E33: The dropbox for this week contains all final documents, media files, and associated build files. | F33: Note: Depending on which files are missing, the team may or may not be able to pass the course.
B35: B04 | C35: =_xlfn.XLOOKUP($B35,'Schedule and Progress'!$B$2:$B$194,'Schedule and Progress'!$C$2:$C$194) -> Project Charter - include updates to all tabs, final version | D35: =_xlfn.XLOOKUP($B35,'Schedule and Progress'!$B$2:$B$187,'Schedule and Progress'!$F$2:$F$187) -> Dropbox6 | E35: Team saved a copy of this Excel file and uploaded it to the dropbox. All student tabs (Summary, latest Contract, Budget, and BOM) are up to date with meaningful information. The proposed project parameters matches the expectations for the course. | F35: Missing information or the required parts are incomplete.
B37: F10-a | C37: =_xlfn.XLOOKUP($B37,'Schedule and Progress'!$B$2:$B$194,'Schedule and Progress'!$C$2:$C$194) -> Demo Live: Final Version of Project Demonstration - show it fully running | D37: =_xlfn.XLOOKUP($B37,'Schedule and Progress'!$B$2:$B$187,'Schedule and Progress'!$F$2:$F$187) -> 0 | E37: Team has brought in a completed prototype of their project and is able to demonstrate it completely working. All features work as expected, including inputs, outputs, IoT interaction, a soldered PCB is installed, and a 3D print installed. The Project's performance and parts fully match the latest version of the Contract. | F37: Note: Depending on which features are missing, incomplete or not working, the team may or may not be able to pass the course.
B39: F10-b | C39: =_xlfn.XLOOKUP($B39,'Schedule and Progress'!$B$2:$B$194,'Schedule and Progress'!$C$2:$C$194) -> Demo Live: Final Version of IoT Dashboard - show it fully running | D39: =_xlfn.XLOOKUP($B39,'Schedule and Progress'!$B$2:$B$187,'Schedule and Progress'!$F$2:$F$187) -> 0 | E39: Team has brought in a completed prototype of their project and is able to demonstrate it completely working. All features work as expected, including inputs, outputs, IoT interaction, a soldered PCB is installed, and a 3D print installed. The Project's performance and parts fully match the latest version of the Contract. | F39: Note: Depending on which features are missing, incomplete or not working, the team may or may not be able to pass the course.
B41: G05-g | C41: =_xlfn.XLOOKUP($B41,'Schedule and Progress'!$B$2:$B$194,'Schedule and Progress'!$C$2:$C$194) -> Updated: All Code (Main & IoT) for entire build, text format | D41: =_xlfn.XLOOKUP($B41,'Schedule and Progress'!$B$2:$B$187,'Schedule and Progress'!$F$2:$F$187) -> #N/A | E41: Team has provided the latest full code for the project, including any code on microcontroller(s), IoT platforms, or similar, in text format in the Technical Report Section 15 Appendix F. The Team is encourage to use a two-row table structure for each major code part, with the file name in the top row and the full text (annotated, indented, black text) in the second row. Comments and annotations are written by the Team and not generated by AI, and are visible throughout major portions of the text. All work is cited. | F41: Missing or incomplete. Missing annotations and full references. One main file contains all code.
